Workbook

Sheet Overview - New
C3: CIS K8S Benchmark 1.12 | D3: NSA-CISA K8S hardening | E3: CIS K8S STIG | F3: BSI K8S | G3: PCI Container Guidance | H3: MS TM 4 K8S | I3: K8S Security Checklists | J3: OWASP K8S Cheat Sheet | K3: KALM Benchmark
A4: Control Plane | B4: Master Node | C4: =COUNTA(_xlfn.UNIQUE('Overall Matcher'!G3:G28))-1 -> 21 | D4: =COUNTA(_xlfn.UNIQUE('Overall Matcher'!H3:H28))-1 -> 2 | E4: =COUNTA(_xlfn.UNIQUE('Overall Matcher'!I3:I28))-1 -> 12 | F4: =COUNTA(_xlfn.UNIQUE('Overall Matcher'!J3:J28))-1 -> 1 | G4: =COUNTA(_xlfn.UNIQUE('Overall Matcher'!K3:K28))-1 -> 1 | H4: =COUNTA(_xlfn.UNIQUE('Overall Matcher'!L3:L28))-1 -> 1 | I4: =COUNTA(_xlfn.UNIQUE('Overall Matcher'!M3:M28))-1 -> 0 | J4: =COUNTA(_xlfn.UNIQUE('Overall Matcher'!N3:N28))-1 -> 1 | K4: =COUNTA(_xlfn.UNIQUE('Overall Matcher'!E3:E28))-1 -> 0
B5: API Server | C5: =COUNTA(_xlfn.UNIQUE('Overall Matcher'!G29:G79))-1 -> 30 | D5: =COUNTA(_xlfn.UNIQUE('Overall Matcher'!H29:H79))-1 -> 7 | E5: =COUNTA(_xlfn.UNIQUE('Overall Matcher'!I29:I79))-1 -> 26 | F5: =COUNTA(_xlfn.UNIQUE('Overall Matcher'!J29:J79))-1 -> 3 | G5: =COUNTA(_xlfn.UNIQUE('Overall Matcher'!K29:K79))-1 -> 5 | H5: =COUNTA(_xlfn.UNIQUE('Overall Matcher'!L29:L79))-1 -> 6 | I5: =COUNTA(_xlfn.UNIQUE('Overall Matcher'!M29:M79))-1 -> 15 | J5: =COUNTA(_xlfn.UNIQUE('Overall Matcher'!N29:N79))-1 -> 4 | K5: =COUNTA(_xlfn.UNIQUE('Overall Matcher'!E29:E79))-1 -> 1
B6: Controller Manager | C6: =COUNTA(_xlfn.UNIQUE('Overall Matcher'!G80:G89))-1 -> 7 | D6: =COUNTA(_xlfn.UNIQUE('Overall Matcher'!H80:H89))-1 -> 3 | E6: =COUNTA(_xlfn.UNIQUE('Overall Matcher'!I80:I89))-1 -> 6 | F6: =COUNTA(_xlfn.UNIQUE('Overall Matcher'!J80:J89))-1 -> 1 | G6: =COUNTA(_xlfn.UNIQUE('Overall Matcher'!K80:K89))-1 -> 6 | H6: =COUNTA(_xlfn.UNIQUE('Overall Matcher'!L80:L89))-1 -> 1 | I6: =COUNTA(_xlfn.UNIQUE('Overall Matcher'!M80:M89))-1 -> 1 | J6: =COUNTA(_xlfn.UNIQUE('Overall Matcher'!N80:N89))-1 -> 1 | K6: =COUNTA(_xlfn.UNIQUE('Overall Matcher'!E80:E89))-1 -> 0
B7: Scheduler | C7: =COUNTA(_xlfn.UNIQUE('Overall Matcher'!G90:G94))-1 -> 2 | D7: =COUNTA(_xlfn.UNIQUE('Overall Matcher'!H90:H94))-1 -> 2 | E7: =COUNTA(_xlfn.UNIQUE('Overall Matcher'!I90:I94))-1 -> 3 | F7: =COUNTA(_xlfn.UNIQUE('Overall Matcher'!J90:J94))-1 -> 0 | G7: =COUNTA(_xlfn.UNIQUE('Overall Matcher'!K90:K94))-1 -> 2 | H7: =COUNTA(_xlfn.UNIQUE('Overall Matcher'!L90:L94))-1 -> 1 | I7: =COUNTA(_xlfn.UNIQUE('Overall Matcher'!M90:M94))-1 -> 0 | J7: =COUNTA(_xlfn.UNIQUE('Overall Matcher'!N90:N94))-1 -> 1 | K7: =COUNTA(_xlfn.UNIQUE('Overall Matcher'!E90:E94))-1 -> 0
B8: etcd | C8: =COUNTA(_xlfn.UNIQUE('Overall Matcher'!G95:G105))-1 -> 7 | D8: =COUNTA(_xlfn.UNIQUE('Overall Matcher'!H95:H105))-1 -> 1 | E8: =COUNTA(_xlfn.UNIQUE('Overall Matcher'!I95:I105))-1 -> 9 | F8: =COUNTA(_xlfn.UNIQUE('Overall Matcher'!J95:J105))-1 -> 1 | G8: =COUNTA(_xlfn.UNIQUE('Overall Matcher'!K95:K105))-1 -> 3 | H8: =COUNTA(_xlfn.UNIQUE('Overall Matcher'!L95:L105))-1 -> 1 | I8: =COUNTA(_xlfn.UNIQUE('Overall Matcher'!M95:M105))-1 -> 3 | J8: =COUNTA(_xlfn.UNIQUE('Overall Matcher'!N95:N105))-1 -> 1 | K8: =COUNTA(_xlfn.UNIQUE('Overall Matcher'!E95:E105))-1 -> 0
B9: Authentication & Authorization | C9: =COUNTA(_xlfn.UNIQUE('Overall Matcher'!G107:G110))-1 -> 3 | D9: =COUNTA(_xlfn.UNIQUE('Overall Matcher'!H107:H110))-1 -> 1 | E9: =COUNTA(_xlfn.UNIQUE('Overall Matcher'!I107:I110))-1 -> 0 | F9: =COUNTA(_xlfn.UNIQUE('Overall Matcher'!J107:J110))-1 -> 1 | G9: =COUNTA(_xlfn.UNIQUE('Overall Matcher'!K107:K110))-1 -> 2 | H9: =COUNTA(_xlfn.UNIQUE('Overall Matcher'!L107:L110))-1 -> 1 | I9: =COUNTA(_xlfn.UNIQUE('Overall Matcher'!M107:M110))-1 -> 0 | J9: =COUNTA(_xlfn.UNIQUE('Overall Matcher'!N107:N110))-1 -> 1 | K9: =COUNTA(_xlfn.UNIQUE('Overall Matcher'!E107:E110))-1 -> 0
B10: Logging | C10: =COUNTA(_xlfn.UNIQUE('Overall Matcher'!G111:G115))-1 -> 2 | D10: =COUNTA(_xlfn.UNIQUE('Overall Matcher'!H111:H115))-1 -> 2 | E10: =COUNTA(_xlfn.UNIQUE('Overall Matcher'!I111:I115))-1 -> 2 | F10: =COUNTA(_xlfn.UNIQUE('Overall Matcher'!J111:J115))-1 -> 0 | G10: =COUNTA(_xlfn.UNIQUE('Overall Matcher'!K111:K115))-1 -> 2 | H10: =COUNTA(_xlfn.UNIQUE('Overall Matcher'!L111:L115))-1 -> 1 | I10: =COUNTA(_xlfn.UNIQUE('Overall Matcher'!M111:M115))-1 -> 1 | J10: =COUNTA(_xlfn.UNIQUE('Overall Matcher'!N111:N115))-1 -> 3 | K10: =COUNTA(_xlfn.UNIQUE('Overall Matcher'!E111:E115))-1 -> 0
A11: Worker Nodes | B11: Worker Node | C11: =COUNTA(_xlfn.UNIQUE('Overall Matcher'!G116:G132))-1 -> 10 | D11: =COUNTA(_xlfn.UNIQUE('Overall Matcher'!H116:H132))-1 -> 2 | E11: =COUNTA(_xlfn.UNIQUE('Overall Matcher'!I116:I132))-1 -> 15 | F11: =COUNTA(_xlfn.UNIQUE('Overall Matcher'!J116:J132))-1 -> 1 | G11: =COUNTA(_xlfn.UNIQUE('Overall Matcher'!K116:K132))-1 -> 1 | H11: =COUNTA(_xlfn.UNIQUE('Overall Matcher'!L116:L132))-1 -> 0 | I11: =COUNTA(_xlfn.UNIQUE('Overall Matcher'!M116:M132))-1 -> 0 | J11: =COUNTA(_xlfn.UNIQUE('Overall Matcher'!N116:N132))-1 -> 0 | K11: =COUNTA(_xlfn.UNIQUE('Overall Matcher'!E116:E121))-1 -> 0
B12: Kubelet | C12: =COUNTA(_xlfn.UNIQUE('Overall Matcher'!G133:G152))-1 -> 14 | D12: =COUNTA(_xlfn.UNIQUE('Overall Matcher'!H133:H152))-1 -> 4 | E12: =COUNTA(_xlfn.UNIQUE('Overall Matcher'!I133:I152))-1 -> 11 | F12: =COUNTA(_xlfn.UNIQUE('Overall Matcher'!J133:J152))-1 -> 2 | G12: =COUNTA(_xlfn.UNIQUE('Overall Matcher'!K133:K152))-1 -> 6 | H12: =COUNTA(_xlfn.UNIQUE('Overall Matcher'!L133:L152))-1 -> 0 | I12: =COUNTA(_xlfn.UNIQUE('Overall Matcher'!M133:M152))-1 -> 1 | J12: =COUNTA(_xlfn.UNIQUE('Overall Matcher'!N133:N152))-1 -> 3 | K12: =COUNTA(_xlfn.UNIQUE('Overall Matcher'!E133:E152))-1 -> 0
B13: kube-proxy | C13: =COUNTA(_xlfn.UNIQUE('Overall Matcher'!G153:G154))-1 -> 1 | D13: =COUNTA(_xlfn.UNIQUE('Overall Matcher'!H153:H154))-1 -> 0 | E13: =COUNTA(_xlfn.UNIQUE('Overall Matcher'!I153:I154))-1 -> 0 | F13: =COUNTA(_xlfn.UNIQUE('Overall Matcher'!J153:J154))-1 -> 0 | G13: =COUNTA(_xlfn.UNIQUE('Overall Matcher'!K153:K154))-1 -> 1 | H13: =COUNTA(_xlfn.UNIQUE('Overall Matcher'!L153:L154))-1 -> 0 | I13: =COUNTA(_xlfn.UNIQUE('Overall Matcher'!M153:M154))-1 -> 0 | J13: =COUNTA(_xlfn.UNIQUE('Overall Matcher'!N153:N154))-1 -> 0 | K13: =COUNTA(_xlfn.UNIQUE('Overall Matcher'!E153:E154))-1 -> 0
A14: Policies | B14: RBAC and Service Accounts | C14: =COUNTA(_xlfn.UNIQUE('Overall Matcher'!G156:G184))-1 -> 13 | D14: =COUNTA(_xlfn.UNIQUE('Overall Matcher'!H156:H184))-1 -> 4 | E14: =COUNTA(_xlfn.UNIQUE('Overall Matcher'!I156:I184))-1 -> 0 | F14: =COUNTA(_xlfn.UNIQUE('Overall Matcher'!J156:J184))-1 -> 3 | G14: =COUNTA(_xlfn.UNIQUE('Overall Matcher'!K156:K184))-1 -> 6 | H14: =COUNTA(_xlfn.UNIQUE('Overall Matcher'!L156:L184))-1 -> 3 | I14: =COUNTA(_xlfn.UNIQUE('Overall Matcher'!M156:M184))-1 -> 10 | J14: =COUNTA(_xlfn.UNIQUE('Overall Matcher'!N156:N184))-1 -> 2 | K14: =COUNTA(_xlfn.UNIQUE('Overall Matcher'!E156:E184))-1 -> 25
B15: Pod Security | C15: =COUNTA(_xlfn.UNIQUE('Overall Matcher'!G185:G228))-1 -> 12 | D15: =COUNTA(_xlfn.UNIQUE('Overall Matcher'!H185:H228))-1 -> 5 | E15: =COUNTA(_xlfn.UNIQUE('Overall Matcher'!I185:I228))-1 -> 3 | F15: =COUNTA(_xlfn.UNIQUE('Overall Matcher'!J185:J228))-1 -> 2 | G15: =COUNTA(_xlfn.UNIQUE('Overall Matcher'!K185:K228))-1 -> 5 | H15: =COUNTA(_xlfn.UNIQUE('Overall Matcher'!L185:L228))-1 -> 5 | I15: =COUNTA(_xlfn.UNIQUE('Overall Matcher'!M185:M228))-1 -> 15 | J15: =COUNTA(_xlfn.UNIQUE('Overall Matcher'!N185:N228))-1 -> 5 | K15: =COUNTA(_xlfn.UNIQUE('Overall Matcher'!E185:E228))-1 -> 34
B16: Network Policies | C16: =COUNTA(_xlfn.UNIQUE('Overall Matcher'!G229:G236))-1 -> 2 | D16: =COUNTA(_xlfn.UNIQUE('Overall Matcher'!H229:H236))-1 -> 3 | E16: =COUNTA(_xlfn.UNIQUE('Overall Matcher'!I229:I236))-1 -> 0 | F16: =COUNTA(_xlfn.UNIQUE('Overall Matcher'!J229:J236))-1 -> 2 | G16: =COUNTA(_xlfn.UNIQUE('Overall Matcher'!K229:K236))-1 -> 1 | H16: =COUNTA(_xlfn.UNIQUE('Overall Matcher'!L229:L236))-1 -> 3 | I16: =COUNTA(_xlfn.UNIQUE('Overall Matcher'!M229:M236))-1 -> 6 | J16: =COUNTA(_xlfn.UNIQUE('Overall Matcher'!N229:N236))-1 -> 2 | K16: =COUNTA(_xlfn.UNIQUE('Overall Matcher'!E229:E236))-1 -> 4
B17: Secrets Management | C17: =COUNTA(_xlfn.UNIQUE('Overall Matcher'!G237:G241))-1 -> 2 | D17: =COUNTA(_xlfn.UNIQUE('Overall Matcher'!H237:H241))-1 -> 0 | E17: =COUNTA(_xlfn.UNIQUE('Overall Matcher'!I237:I241))-1 -> 1 | F17: =COUNTA(_xlfn.UNIQUE('Overall Matcher'!J237:J241))-1 -> 0 | G17: =COUNTA(_xlfn.UNIQUE('Overall Matcher'!K237:K241))-1 -> 3 | H17: =COUNTA(_xlfn.UNIQUE('Overall Matcher'!L237:L241))-1 -> 2 | I17: =COUNTA(_xlfn.UNIQUE('Overall Matcher'!M237:M241))-1 -> 3 | J17: =COUNTA(_xlfn.UNIQUE('Overall Matcher'!N237:N241))-1 -> 2 | K17: =COUNTA(_xlfn.UNIQUE('Overall Matcher'!E237:E241))-1 -> 2
B18: Extensible Admission Control | C18: =COUNTA(_xlfn.UNIQUE('Overall Matcher'!G242:G244))-1 -> 1 | D18: =COUNTA(_xlfn.UNIQUE('Overall Matcher'!H242:H244))-1 -> 0 | E18: =COUNTA(_xlfn.UNIQUE('Overall Matcher'!I242:I244))-1 -> 0 | F18: =COUNTA(_xlfn.UNIQUE('Overall Matcher'!J242:J244))-1 -> 0 | G18: =COUNTA(_xlfn.UNIQUE('Overall Matcher'!K242:K244))-1 -> 2 | H18: =COUNTA(_xlfn.UNIQUE('Overall Matcher'!L242:L244))-1 -> 1 | I18: =COUNTA(_xlfn.UNIQUE('Overall Matcher'!M242:M244))-1 -> 2 | J18: =COUNTA(_xlfn.UNIQUE('Overall Matcher'!N242:N244))-1 -> 1 | K18: =COUNTA(_xlfn.UNIQUE('Overall Matcher'!E242:E244))-1 -> 1
B19: General Policies | C19: =COUNTA(_xlfn.UNIQUE('Overall Matcher'!G245:G264))-1 -> 4 | D19: =COUNTA(_xlfn.UNIQUE('Overall Matcher'!H245:H264))-1 -> 3 | E19: =COUNTA(_xlfn.UNIQUE('Overall Matcher'!I245:I264))-1 -> 5 | F19: =COUNTA(_xlfn.UNIQUE('Overall Matcher'!J245:J264))-1 -> 3 | G19: =COUNTA(_xlfn.UNIQUE('Overall Matcher'!K245:K264))-1 -> 5 | H19: =COUNTA(_xlfn.UNIQUE('Overall Matcher'!L245:L264))-1 -> 2 | I19: =COUNTA(_xlfn.UNIQUE('Overall Matcher'!M245:M264))-1 -> 5 | J19: =COUNTA(_xlfn.UNIQUE('Overall Matcher'!N245:N264))-1 -> 3 | K19: =COUNTA(_xlfn.UNIQUE('Overall Matcher'!E245:E264))-1 -> 10
B21: Target | C21: =COUNTA(_xlfn.UNIQUE('CIS Kubernetes 1.12'!C6:C156))-20 -> 131 | D21: 30 | E21: =COUNTA(_xlfn.UNIQUE('K8S STIG'!B6:B96)) -> 91 | F21: =COUNTA(_xlfn.UNIQUE(BSI!A5:A28))-3 -> 21 | G21: =COUNTA(_xlfn.UNIQUE('PCI Container Guidance'!A5:A69))-16 -> 49 | H21: =COUNTA(_xlfn.UNIQUE('MS TM for K8S'!A5:A39)) -> 35 | I21: =COUNTA(_xlfn.UNIQUE('Kubernetes security checklists'!C5:C81)) -> 76 | J21: =SUM(OWASP!D7:D66) -> 53 | K21: =COUNTA(_xlfn.UNIQUE('KALM-Checks'!B4:B87)) -> 84
B22: Current | C22: =COUNTA(_xlfn.UNIQUE('Overall Matcher'!G3:G1032))-1 -> 131 | D22: =COUNTA(_xlfn.UNIQUE('Overall Matcher'!H3:H1032))-1 -> 23 | E22: =COUNTA(_xlfn.UNIQUE('Overall Matcher'!I3:I1032))-1 -> 88 | F22: =COUNTA(_xlfn.UNIQUE('Overall Matcher'!J3:J1032))-1 -> 10 | G22: =COUNTA(_xlfn.UNIQUE('Overall Matcher'!K3:K1032))-1 -> 31 | H22: =COUNTA(_xlfn.UNIQUE('Overall Matcher'!L3:L1032))-1 -> 22 | I22: =COUNTA(_xlfn.UNIQUE('Overall Matcher'!M3:M1032))-1 -> 60 | J22: =COUNTA(_xlfn.UNIQUE('Overall Matcher'!N3:N1032))-1 -> 24 | K22: =COUNTA(_xlfn.UNIQUE('Overall Matcher'!E3:E1032))-1 -> 77
B23: Not mapped | C23: =C21-C22 -> 0 | D23: =D21-D22 -> 7 | E23: =E21-E22 -> 3 | F23: =F21-F22 -> 11 | G23: =G21-G22 -> 18 | H23: =H21-H22 -> 13 | I23: =I21-I22 -> 16 | J23: =J21-J22 -> 29 | K23: =K21-K22 -> 7
B24: Unmapped % | C24: =1-C22/C21 -> 0 | D24: =1-D22/D21 -> 0.23333333 | E24: =1-E22/E21 -> 0.032967033 | F24: =1-F22/F21 -> 0.52380952 | G24: =1-G22/G21 -> 0.36734694 | H24: =1-H22/H21 -> 0.37142857 | I24: =1-I22/I21 -> 0.21052632 | J24: =1-J22/J21 -> 0.54716981 | K24: =1-K22/K21 -> 0.083333333
B25: Mapped % | C25: =C22/C21 -> 1 | D25: =D22/D21 -> 0.76666667 | E25: =E22/E21 -> 0.96703297 | F25: =F22/F21 -> 0.47619048 | G25: =G22/G21 -> 0.63265306 | H25: =H22/H21 -> 0.62857143 | I25: =I22/I21 -> 0.78947368 | J25: =J22/J21 -> 0.45283019 | K25: =K22/K21 -> 0.91666667

Sheet Overall Matcher
A1: Section | B1: Description | C1: Origin | D1: Origin-Numbering | E1: KALM Benchmark check | G1: CIS Kubernetes 1.12 | H1: NSA-CISA k8s hardening | I1: k8s STIG | J1: BSI | K1: PCI Container Guidance | L1: Microsoft Threat Matrix for Kubernetes | M1: k8s security checklists | N1: OWASP
A2: Control Plane Components
B3: Kubernetes Kubectl cp command must give expected access and results. | C3: k8s STIG | D3: V-242396 | I3: ='K8S STIG'!B26 -> V-242396
B4: Kubernetes DynamicAuditing must not be enabled. | C4: k8s STIG | D4: V-242398 | I4: ='K8S STIG'!B28 -> V-242398
B5: Kubernetes must contain the latest updates as authorized by IAVMs, CTOs, DTMs, and STIGs. | C5: k8s STIG | D5: V-242443 | H5: ='NSA-CISA k8s hardening'!A$38 -> Upgrading and application security practices | I5: ='K8S STIG'!B73 -> V-242443 | K5: ='PCI Container Guidance'!A42 -> 10.1.a | N5: =OWASP!B7 -> Updating Kubernetes
A6: Control Plane Node Configuration Files
B7: Ensure that the API server pod specification file permissions are set to 600 or more restrictive | C7: CIS Kubernetes Benchmark | D7: 1.1.1 | G7: 1.1.1 | I7: ='K8S STIG'!B37 -> V-242408 | J7: =BSI!A$14 -> APP.4.4.A8 | L7: ='MS TM for K8S'!A$23 -> MS-M9016
B8: Ensure that the API server pod specification file ownership is set to root:root | C8: CIS Kubernetes Benchmark | D8: 1.1.2 | G8: 1.1.2 | I8: ='K8S STIG'!B$34 -> V-242405 | J8: =BSI!A$14 -> APP.4.4.A8 | L8: ='MS TM for K8S'!A$23 -> MS-M9016
B9: Ensure that the controller manager pod specification file permissions are set to 600 or more restrictive | C9: CIS Kubernetes Benchmark | D9: 1.1.3 | G9: 1.1.3 | I9: ='K8S STIG'!B$37 -> V-242408 | J9: =BSI!A$14 -> APP.4.4.A8 | L9: ='MS TM for K8S'!A$23 -> MS-M9016
B10: Ensure that the controller manager pod specification file ownership is set to root:root | C10: CIS Kubernetes Benchmark | D10: 1.1.4 | G10: 1.1.4 | I10: ='K8S STIG'!B$34 -> V-242405 | J10: =BSI!A$14 -> APP.4.4.A8 | L10: ='MS TM for K8S'!A$23 -> MS-M9016
B11: Ensure that the scheduler pod specification file permissions are set to 600 or more restrictive | C11: CIS Kubernetes Benchmark | D11: 1.1.5 | G11: 1.1.5 | I11: ='K8S STIG'!B$37 -> V-242408 | J11: =BSI!A$14 -> APP.4.4.A8 | L11: ='MS TM for K8S'!A$23 -> MS-M9016
B12: Ensure that the scheduler pod specification file ownership is set to root:root | C12: CIS Kubernetes Benchmark | D12: 1.1.6 | G12: 1.1.6 | I12: ='K8S STIG'!B$34 -> V-242405 | J12: =BSI!A$14 -> APP.4.4.A8 | L12: ='MS TM for K8S'!A$23 -> MS-M9016
B13: Ensure that the etcd pod specification file permissions are set to 600 or more restrictive | C13: CIS Kubernetes Benchmark | D13: 1.1.7 | G13: 1.1.7 | I13: ='K8S STIG'!B$37 -> V-242408 | J13: =BSI!A$14 -> APP.4.4.A8 | L13: ='MS TM for K8S'!A$23 -> MS-M9016
B14: Ensure that the etcd pod specification file ownership is set to root:root | C14: CIS Kubernetes Benchmark | D14: 1.1.8 | G14: 1.1.8 | I14: ='K8S STIG'!B$34 -> V-242405 | J14: =BSI!A$14 -> APP.4.4.A8 | L14: ='MS TM for K8S'!A$23 -> MS-M9016
B15: Ensure that the Container Network Interface file permissions are set to 600 or more restrictive | C15: CIS Kubernetes Benchmark | D15: 1.1.9 | G15: 1.1.9 | I15: ='K8S STIG'!B$37 -> V-242408 | J15: =BSI!A$14 -> APP.4.4.A8
B16: Ensure that the Container Network Interface file ownership is set to root:root | C16: CIS Kubernetes Benchmark | D16: 1.1.10 | G16: 1.1.10 | I16: ='K8S STIG'!B$34 -> V-242405 | J16: =BSI!A$14 -> APP.4.4.A8
B17: Ensure that the etcd data directory permissions are set to 700 or more restrictive | C17: CIS Kubernetes Benchmark | D17: 1.1.11 | G17: 1.1.11 | I17: ='K8S STIG'!B88 -> V-242459 | J17: =BSI!A$14 -> APP.4.4.A8
B18: Ensure that the etcd data directory ownership is set to etcd:etcd | C18: CIS Kubernetes Benchmark | D18: 1.1.12 | G18: 1.1.12 | I18: ='K8S STIG'!B75 -> V-242445 | J18: =BSI!A$14 -> APP.4.4.A8
B19: Ensure that the default administrative credential file permissions are set to 600 | C19: CIS Kubernetes Benchmark | D19: 1.1.13 | G19: 1.1.13 | H19: ='NSA-CISA k8s hardening'!C$18 -> Kubeconfig Files | I19: ='K8S STIG'!B89 -> V-242460 | J19: =BSI!A$14 -> APP.4.4.A8
B20: Ensure that the default administrative credential file ownership is set to root:root | C20: CIS Kubernetes Benchmark | D20: 1.1.14 | G20: 1.1.14 | H20: ='NSA-CISA k8s hardening'!C$18 -> Kubeconfig Files | I20: ='K8S STIG'!B$76 -> V-242446 | J20: =BSI!A$14 -> APP.4.4.A8
B21: Ensure that the scheduler.conf file permissions are set to 600 or more restrictive | C21: CIS Kubernetes Benchmark | D21: 1.1.15 | G21: 1.1.15 | H21: ='NSA-CISA k8s hardening'!C$18 -> Kubeconfig Files | I21: ='K8S STIG'!B89 -> V-242460 | J21: =BSI!A$14 -> APP.4.4.A8
B22: Ensure that the scheduler.conf file ownership is set to root:root | C22: CIS Kubernetes Benchmark | D22: 1.1.16 | G22: 1.1.16 | H22: ='NSA-CISA k8s hardening'!C$18 -> Kubeconfig Files | I22: ='K8S STIG'!B$76 -> V-242446 | J22: =BSI!A$14 -> APP.4.4.A8
B23: Ensure that the controller-manager.conf file permissions are set to 600 or more restrictive | C23: CIS Kubernetes Benchmark | D23: 1.1.17 | G23: 1.1.17 | H23: ='NSA-CISA k8s hardening'!C$18 -> Kubeconfig Files | I23: ='K8S STIG'!B89 -> V-242460 | J23: =BSI!A$14 -> APP.4.4.A8
B24: Ensure that the controller-manager.conf file ownership is set to root:root | C24: CIS Kubernetes Benchmark | D24: 1.1.18 | G24: 1.1.18 | H24: ='NSA-CISA k8s hardening'!C$18 -> Kubeconfig Files | I24: ='K8S STIG'!B$76 -> V-242446 | J24: =BSI!A$14 -> APP.4.4.A8
B25: Ensure that the Kubernetes PKI directory and file ownership is set to root:root | C25: CIS Kubernetes Benchmark | D25: 1.1.19 | G25: 1.1.19 | I25: ='K8S STIG'!B81 -> V-242451 | J25: =BSI!A$14 -> APP.4.4.A8
B26: Ensure that the Kubernetes PKI certificate file permissions are set to 644 or more restrictive | C26: CIS Kubernetes Benchmark | D26: 1.1.20 | G26: 1.1.20 | I26: ='K8S STIG'!B95 -> V-242466 | J26: =BSI!A$14 -> APP.4.4.A8
B27: Ensure that the Kubernetes PKI key file permissions are set to 600 | C27: CIS Kubernetes Benchmark | D27: 1.1.21 | G27: 1.1.21 | I27: ='K8S STIG'!B96 -> V-242467 | J27: =BSI!A$14 -> APP.4.4.A8
A28: API Server
B29: Ensure that the --anonymous-auth argument is set to false | C29: CIS Kubernetes Benchmark | D29: 1.2.1 | G29: 1.2.1 | H29: ='NSA-CISA k8s hardening'!B$24 -> Authentication | I29: ='K8S STIG'!B20 -> V-242390 | J29: =BSI!A$8 -> APP.4.4.A3 | L29: ='MS TM for K8S'!A$28 -> MS-M9021
B30: Ensure that the --token-auth-file parameter is not set | C30: CIS Kubernetes Benchmark | D30: 1.2.2 | G30: 1.2.2 | I30: ='K8S STIG'!B70 -> V-245543 | K30: ='PCI Container Guidance'!A8 -> 1.3.a | L30: ='MS TM for K8S'!A$28 -> MS-M9021
B31: Ensure that the DenyServiceExternalIPs is set | C31: CIS Kubernetes Benchmark | D31: 1.2.3 | G31: 1.2.3 | H31: ='NSA-CISA k8s hardening'!B16 -> Control plane hardening | K31: ='PCI Container Guidance'!A24 -> 4.2.a | L31: ='MS TM for K8S'!A$15 -> MS-M9008 | M31: ='Kubernetes security checklists'!C16 -> Use of LoadBalancer and ExternalIPs is restricted.
M32: ='Kubernetes security checklists'!C55 -> DenyServiceExternalIPs - Rejects all net-new usage of the Service.spec.externalIPs field. This is a mitigation for CVE-2020-8554: Man in the middle using LoadBalancer or ExternalIPs.
B33: Ensure that the --kubelet-client-certificate and --kubelet-client-key arguments are set as appropriate | C33: CIS Kubernetes Benchmark | D33: 1.2.4 | G33: 1.2.4 | H33: ='NSA-CISA k8s hardening'!B16 -> Control plane hardening | I33: ='K8S STIG'!B71 -> V-245544 | K33: ='PCI Container Guidance'!A25 -> 4.3.a
B34: Ensure that the --kubelet-certificate-authority argument is set as appropriate | C34: CIS Kubernetes Benchmark | D34: 1.2.5 | G34: 1.2.5 | H34: ='NSA-CISA k8s hardening'!B16 -> Control plane hardening | K34: ='PCI Container Guidance'!A29 -> 5.2.a
B35: Ensure that the --authorization-mode argument is not set to AlwaysAllow | C35: CIS Kubernetes Benchmark | D35: 1.2.6 | G35: 1.2.6 | H35: ='NSA-CISA k8s hardening'!B$25 -> Role-based access control | I35: ='K8S STIG'!B21 -> V-242392 | J35: =BSI!A$8 -> APP.4.4.A3 | L35: ='MS TM for K8S'!A$28 -> MS-M9021
B36: Ensure that the --authorization-mode argument includes Node | C36: CIS Kubernetes Benchmark | D36: 1.2.7 | G36: 1.2.7 | I36: ='K8S STIG'!B12 -> V-242382
B37: Ensure that the --authorization-mode argument includes RBAC | C37: CIS Kubernetes Benchmark | D37: 1.2.8 | G37: 1.2.8 | H37: ='NSA-CISA k8s hardening'!B$16 -> Control plane hardening | I37: ='K8S STIG'!B12 -> V-242382 | J37: =BSI!A$8 -> APP.4.4.A3 | L37: ='MS TM for K8S'!A$28 -> MS-M9021 | N37: =OWASP!B17 -> Implementing Role-Based Access Control in Kubernetes
B38: Ensure that the admission control plugin EventRateLimit is set | C38: CIS Kubernetes Benchmark | D38: 1.2.9 | G38: 1.2.9
B39: Ensure that the admission control plugin AlwaysAdmit is not set | C39: CIS Kubernetes Benchmark | D39: 1.2.10 | G39: 1.2.10
B40: Ensure that the admission control plugin AlwaysPullImages is set | C40: CIS Kubernetes Benchmark | D40: 1.2.11 | E40: ='KALM-Checks'!B85 -> SC-001 | G40: 1.2.11 | M40: ='Kubernetes security checklists'!C57 -> AlwaysPullImages - Enforces the usage of the latest version of a tagged image and ensures that the deployer has permissions to use the image.
...

Sheet KALM-Checks
B1: KALM Benchmark Implementations
B3: Numbering | C3: Category | D3: Description
A4: =MATCH(B4, 'Overall Matcher'!$E$3:$E$1023, 0) -> 238 | B4: CM-001 | C4: ConfigMap | D4: storing secretes in ConfigMap
A5: =MATCH(B5, 'Overall Matcher'!$E$3:$E$1023, 0) -> 229 | B5: NP-001 | C5: Network Policy | D5: Namespace without network policy
A6: =MATCH(B6, 'Overall Matcher'!$E$3:$E$1023, 0) -> 231 | B6: NP-002 | C6: Network Policy | D6: network policy blocking ingress and egress
A7: =MATCH(B7, 'Overall Matcher'!$E$3:$E$1023, 0) -> 232 | B7: NP-003 | C7: Network Policy | D7: network policy allowing access to cloud metadata API
A8: =MATCH(B8, 'Overall Matcher'!$E$3:$E$1023, 0) -> 230 | B8: NP-004 | C8: Network Policy | D8: network policy allowing access to kubelet
A9: =MATCH(B9, 'Overall Matcher'!$E$3:$E$1023, 0) -> #N/A | B9: NP-005 | C9: Network Policy | D9: network policy refering to non-existing workload
A10: =MATCH(B10, 'Overall Matcher'!$E$3:$E$1023, 0) -> 250 | B10: NS-001 | C10: Namespace | D10: do not place pods in default namespace
A11: =MATCH(B11, 'Overall Matcher'!$E$3:$E$1023, 0) -> 243 | B11: NS-002 | C11: Namespace | D11: do not place pods in existing namespaces
A12: =MATCH(B12, 'Overall Matcher'!$E$3:$E$1023, 0) -> 159 | B12: POD-002 | C12: Pod Security Standards | D12: do not use default serviceAccount
A13: =MATCH(B13, 'Overall Matcher'!$E$3:$E$1023, 0) -> 161 | B13: POD-003 | C13: Pod Security Standards | D13: automountServiceAccountToken
A14: =MATCH(B14, 'Overall Matcher'!$E$3:$E$1023, 0) -> 185 | B14: POD-008 | C14: Pod Security Standards | D14: minimize usage of hostPID
A15: =MATCH(B15, 'Overall Matcher'!$E$3:$E$1023, 0) -> 186 | B15: POD-009 | C15: Pod Security Standards | D15: minimize usage of hostIPC
... A17: =MATCH(B17, 'Overall Matcher'!$E$3:$E$1023, 0) -> 205 | B17: POD-011 | C17: Pod Security Standards | D17: minimize usage of hostPorts
A18: =MATCH(B18, 'Overall Matcher'!$E$3:$E$1023, 0) -> #N/A | B18: POD-012 | C18: Pod Security Standards | D18: managing /etc/hosts can prevent Docker from modifying it | E18: (deprecated?)
A19: =MATCH(B19, 'Overall Matcher'!$E$3:$E$1023, 0) -> #N/A | B19: POD-013 | C19: Pod Security Standards | D19: use of deprecated serviceAccount instead of serviceAccountName
A20: =MATCH(B20, 'Overall Matcher'!$E$3:$E$1023, 0) -> 222 | B20: POD-014 | C20: Pod Security Standards | D20: use apparmor
A21: =MATCH(B21, 'Overall Matcher'!$E$3:$E$1023, 0) -> 245 | B21: POD-015 | C21: Pod Security Standards | D21: use seccomp
A22: =MATCH(B22, 'Overall Matcher'!$E$3:$E$1023, 0) -> 248 | B22: POD-016 | C22: Pod Security Standards | D22: podSecurityContext
A23: =MATCH(B23, 'Overall Matcher'!$E$3:$E$1023, 0) -> 190 | B23: POD-017 | C23: Pod Security Standards | D23: runAsNonRoot
A24: =MATCH(B24, 'Overall Matcher'!$E$3:$E$1023, 0) -> 191 | B24: POD-018 | C24: Pod Security Standards | D24: runAsUser
A25: =MATCH(B25, 'Overall Matcher'!$E$3:$E$1023, 0) -> 192 | B25: POD-019 | C25: Pod Security Standards | D25: do not run with default GID 0
A26: =MATCH(B26, 'Overall Matcher'!$E$3:$E$1023, 0) -> #N/A | B26: POD-021 | C26: Pod Security Standards | D26: do not use unsafe sysctls | E26: for refinement see https://kubernetes.io/docs/tasks/administer-cluster/sysctl-cluster/
A27: =MATCH(B27, 'Overall Matcher'!$E$3:$E$1023, 0) -> 223 | B27: POD-022 | C27: Pod Security Standards | D27: hardening via apparmor or selinux or seccomp
A28: =MATCH(B28, 'Overall Matcher'!$E$3:$E$1023, 0) -> 246 | B28: POD-023 | C28: Pod Security Standards | D28: not providing a seccomp profile allows more capabilities than necessary | E28: needs refinement
A29: =MATCH(B29, 'Overall Matcher'!$E$3:$E$1023, 0) -> #N/A | B29: POD-024 | C29: Pod Security Standards | D29: attackers who can run a cmd/bash script can use it to execute malicious code
A30: =MATCH(B30, 'Overall Matcher'!$E$3:$E$1023, 0) -> 235 | B30: POD-025 | C30: Pod Security Standards | D30: do not use secrets in environment variables
A31: =MATCH(B31, 'Overall Matcher'!$E$3:$E$1023, 0) -> 249 | B31: POD-030 | C31: Pod Security Standards | D31: no security context
A32: =MATCH(B32, 'Overall Matcher'!$E$3:$E$1023, 0) -> 188 | B32: POD-031 | C32: Pod Security Standards | D32: allowPrivilegeEscalation
A33: =MATCH(B33, 'Overall Matcher'!$E$3:$E$1023, 0) -> 184 | B33: POD-032 | C33: Pod Security Standards | D33: privileged container
A34: =MATCH(B34, 'Overall Matcher'!$E$3:$E$1023, 0) -> 207 | B34: POD-033 | C34: Pod Security Standards | D34: immutable file system should be used
A35: =MATCH(B35, 'Overall Matcher'!$E$3:$E$1023, 0) -> 196 | B35: POD-034 | C35: Pod Security Standards | D35: adding dangerous capabilities
A36: =MATCH(B36, 'Overall Matcher'!$E$3:$E$1023, 0) -> 198 | B36: POD-035 | C36: Pod Security Standards | D36: adding insecure capabilities
A37: =MATCH(B37, 'Overall Matcher'!$E$3:$E$1023, 0) -> 199 | B37: POD-036 | C37: Pod Security Standards | D37: keep default capabilities
A38: =MATCH(B38, 'Overall Matcher'!$E$3:$E$1023, 0) -> 201 | B38: POD-042 | C38: Pod Security Standards | D38: mount of hostPath
A39: =MATCH(B39, 'Overall Matcher'!$E$3:$E$1023, 0) -> 202 | B39: POD-043 | C39: Pod Security Standards | D39: mount of azure credentials file | E39: rework description in rule
A40: =MATCH(B40, 'Overall Matcher'!$E$3:$E$1023, 0) -> 203 | B40: POD-044 | C40: Pod Security Standards | D40: mount of docker socket
A41: =MATCH(B41, 'Overall Matcher'!$E$3:$E$1023, 0) -> 204 | B41: POD-045 | C41: Pod Security Standards | D41: Volume mount with subPath or subPathExpr
A42: =MATCH(B42, 'Overall Matcher'!$E$3:$E$1023, 0) -> 200 | B42: POD-046 | C42: Pod Security Standards | D42: Minimize the admission of Windows HostProcess
...

Sheet CIS Kubernetes 1.12
A1: Title | B1: CIS Kubernetes Benchmark | L1: 0.395 (local) | M1: 0.45 (multi auth) | N1: 0.35 (high) | O1: 0.0 (none) | P1: 0.0 (none) | Q1: 0.0 (none)
A2: Version | B2: 1.12 | L2: 0.646 (adj) | M2: 0.56 (single auth) | N2: 0.61 (medium) | O2: 0.275 (partial) | P2: 0.275 (partial) | Q2: 0.275 (partial)
L3: 1.0 (network) | M3: 0.704 (no auth) | N3: 0.71 (low) | O3: 0.660 (complete) | P3: 0.660 (complete) | Q3: 0.660 (complete)
A5: Section | B5: Subsection | C5: Numbering | D5: Title | E5: Automated | F5: CCSS rating | G5: CCSS score | H5: Exploitability | I5: f(Impact) | J5: Impact | K5: CCSS score (by M365 Copilot) | L5: AccessVector | M5: Authentication | N5: AccessComplexity | O5: Confidentiality | P5: Availability | Q5: Integrity
A6: Control Plane Components | C6: 1
B7: Control Plane Node Configuration Files | C7: 1.1
C8: 1.1.1 | D8: Ensure that the API server pod specification file permissions are set to 600 or more restrictive | E8: 1 | F8: =IF(G8=0, "NONE", IF(G8<4, "LOW", IF(G8<7, "MEDIUM", IF(G8<9, "HIGH", "CRITICAL")))) -> LOW | G8: =ROUND(((0.6*J8)+(0.4*H8)-1.5)*I8,1) -> 3 | H8: =20*L8*M8*N8 -> 2.69864 | I8: =IF(J8=0, 0, 1.176) -> 1.176 | J8: =10.41*(1-(1-O8)*(1-P8)*(1-Q8)) -> 4.9382437 | L8: 0.395 | M8: 0.56 | N8: 0.61 | O8: 0.275 | P8: 0 | Q8: 0.275
C9: 1.1.2 | D9: Ensure that the API server pod specification file ownership is set to root:root | E9: 1 | F9: =IF(G9=0, "NONE", IF(G9<4, "LOW", IF(G9<7, "MEDIUM", IF(G9<9, "HIGH", "CRITICAL")))) -> LOW | G9: =ROUND(((0.6*J9)+(0.4*H9)-1.5)*I9,1) -> 3 | H9: =20*L9*M9*N9 -> 2.69864 | I9: =IF(J9=0, 0, 1.176) -> 1.176 | J9: =10.41*(1-(1-O9)*(1-P9)*(1-Q9)) -> 4.9382437 | L9: 0.395 | M9: 0.56 | N9: 0.61 | O9: 0.275 | P9: 0 | Q9: 0.275
C10: 1.1.3 | D10: Ensure that the controller manager pod specification file permissions are set to 600 or more restrictive | E10: 1 | F10: =IF(G10=0, "NONE", IF(G10<4, "LOW", IF(G10<7, "MEDIUM", IF(G10<9, "HIGH", "CRITICAL")))) -> LOW | G10: =ROUND(((0.6*J10)+(0.4*H10)-1.5)*I10,1) -> 3 | H10: =20*L10*M10*N10 -> 2.69864 | I10: =IF(J10=0, 0, 1.176) -> 1.176 | J10: =10.41*(1-(1-O10)*(1-P10)*(1-Q10)) -> 4.9382437 | L10: 0.395 | M10: 0.56 | N10: 0.61 | O10: 0.275 | P10: 0 | Q10: 0.275
C11: 1.1.4 | D11: Ensure that the controller manager pod specification file ownership is set to root:root | E11: 1 | F11: =IF(G11=0, "NONE", IF(G11<4, "LOW", IF(G11<7, "MEDIUM", IF(G11<9, "HIGH", "CRITICAL")))) -> LOW | G11: =ROUND(((0.6*J11)+(0.4*H11)-1.5)*I11,1) -> 3 | H11: =20*L11*M11*N11 -> 2.69864 | I11: =IF(J11=0, 0, 1.176) -> 1.176 | J11: =10.41*(1-(1-O11)*(1-P11)*(1-Q11)) -> 4.9382437 | L11: 0.395 | M11: 0.56 | N11: 0.61 | O11: 0.275 | P11: 0 | Q11: 0.275
C12: 1.1.5 | D12: Ensure that the scheduler pod specification file permissions are set to 600 or more restrictive | E12: 1 | F12: =IF(G12=0, "NONE", IF(G12<4, "LOW", IF(G12<7, "MEDIUM", IF(G12<9, "HIGH", "CRITICAL")))) -> LOW | G12: =ROUND(((0.6*J12)+(0.4*H12)-1.5)*I12,1) -> 3 | H12: =20*L12*M12*N12 -> 2.69864 | I12: =IF(J12=0, 0, 1.176) -> 1.176 | J12: =10.41*(1-(1-O12)*(1-P12)*(1-Q12)) -> 4.9382437 | L12: 0.395 | M12: 0.56 | N12: 0.61 | O12: 0.275 | P12: 0 | Q12: 0.275
C13: 1.1.6 | D13: Ensure that the scheduler pod specification file ownership is set to root:root | E13: 1 | F13: =IF(G13=0, "NONE", IF(G13<4, "LOW", IF(G13<7, "MEDIUM", IF(G13<9, "HIGH", "CRITICAL")))) -> LOW | G13: =ROUND(((0.6*J13)+(0.4*H13)-1.5)*I13,1) -> 3 | H13: =20*L13*M13*N13 -> 2.69864 | I13: =IF(J13=0, 0, 1.176) -> 1.176 | J13: =10.41*(1-(1-O13)*(1-P13)*(1-Q13)) -> 4.9382437 | L13: 0.395 | M13: 0.56 | N13: 0.61 | O13: 0.275 | P13: 0 | Q13: 0.275
C14: 1.1.7 | D14: Ensure that the etcd pod specification file permissions are set to 600 or more restrictive | E14: 1 | F14: =IF(G14=0, "NONE", IF(G14<4, "LOW", IF(G14<7, "MEDIUM", IF(G14<9, "HIGH", "CRITICAL")))) -> LOW | G14: =ROUND(((0.6*J14)+(0.4*H14)-1.5)*I14,1) -> 3 | H14: =20*L14*M14*N14 -> 2.69864 | I14: =IF(J14=0, 0, 1.176) -> 1.176 | J14: =10.41*(1-(1-O14)*(1-P14)*(1-Q14)) -> 4.9382437 | L14: 0.395 | M14: 0.56 | N14: 0.61 | O14: 0.275 | P14: 0 | Q14: 0.275
C15: 1.1.8 | D15: Ensure that the etcd pod specification file ownership is set to root:root | E15: 1 | F15: =IF(G15=0, "NONE", IF(G15<4, "LOW", IF(G15<7, "MEDIUM", IF(G15<9, "HIGH", "CRITICAL")))) -> LOW | G15: =ROUND(((0.6*J15)+(0.4*H15)-1.5)*I15,1) -> 3 | H15: =20*L15*M15*N15 -> 2.69864 | I15: =IF(J15=0, 0, 1.176) -> 1.176 | J15: =10.41*(1-(1-O15)*(1-P15)*(1-Q15)) -> 4.9382437 | L15: 0.395 | M15: 0.56 | N15: 0.61 | O15: 0.275 | P15: 0 | Q15: 0.275
C16: 1.1.9 | D16: Ensure that the Container Network Interface file permissions are set to 600 or more restrictive | E16: 0 | F16: =IF(G16=0, "NONE", IF(G16<4, "LOW", IF(G16<7, "MEDIUM", IF(G16<9, "HIGH", "CRITICAL")))) -> LOW | G16: =ROUND(((0.6*J16)+(0.4*H16)-1.5)*I16,1) -> 3 | H16: =20*L16*M16*N16 -> 2.69864 | I16: =IF(J16=0, 0, 1.176) -> 1.176 | J16: =10.41*(1-(1-O16)*(1-P16)*(1-Q16)) -> 4.9382437 | L16: 0.395 | M16: 0.56 | N16: 0.61 | O16: 0.275 | P16: 0 | Q16: 0.275
C17: 1.1.10 | D17: Ensure that the Container Network Interface file ownership is set to root:root | E17: 0 | F17: =IF(G17=0, "NONE", IF(G17<4, "LOW", IF(G17<7, "MEDIUM", IF(G17<9, "HIGH", "CRITICAL")))) -> LOW | G17: =ROUND(((0.6*J17)+(0.4*H17)-1.5)*I17,1) -> 3 | H17: =20*L17*M17*N17 -> 2.69864 | I17: =IF(J17=0, 0, 1.176) -> 1.176 | J17: =10.41*(1-(1-O17)*(1-P17)*(1-Q17)) -> 4.9382437 | L17: 0.395 | M17: 0.56 | N17: 0.61 | O17: 0.275 | P17: 0 | Q17: 0.275
C18: 1.1.11 | D18: Ensure that the etcd data directory permissions are set to 700 or more restrictive | E18: 1 | F18: =IF(G18=0, "NONE", IF(G18<4, "LOW", IF(G18<7, "MEDIUM", IF(G18<9, "HIGH", "CRITICAL")))) -> LOW | G18: =ROUND(((0.6*J18)+(0.4*H18)-1.5)*I18,1) -> 3 | H18: =20*L18*M18*N18 -> 2.69864 | I18: =IF(J18=0, 0, 1.176) -> 1.176 | J18: =10.41*(1-(1-O18)*(1-P18)*(1-Q18)) -> 4.9382437 | L18: 0.395 | M18: 0.56 | N18: 0.61 | O18: 0.275 | P18: 0 | Q18: 0.275
C19: 1.1.12 | D19: Ensure that the etcd data directory ownership is set to etcd:etcd | E19: 1 | F19: =IF(G19=0, "NONE", IF(G19<4, "LOW", IF(G19<7, "MEDIUM", IF(G19<9, "HIGH", "CRITICAL")))) -> LOW | G19: =ROUND(((0.6*J19)+(0.4*H19)-1.5)*I19,1) -> 3 | H19: =20*L19*M19*N19 -> 2.69864 | I19: =IF(J19=0, 0, 1.176) -> 1.176 | J19: =10.41*(1-(1-O19)*(1-P19)*(1-Q19)) -> 4.9382437 | L19: 0.395 | M19: 0.56 | N19: 0.61 | O19: 0.275 | P19: 0 | Q19: 0.275
... C28: 1.1.21 | D28: Ensure that the Kubernetes PKI key file permissions are set to 600 | E28: 0 | F28: =IF(G28=0, "NONE", IF(G28<4, "LOW", IF(G28<7, "MEDIUM", IF(G28<9, "HIGH", "CRITICAL")))) -> MEDIUM | G28: =ROUND(((0.6*J28)+(0.4*H28)-1.5)*I28,1) -> 6 | H28: =20*L28*M28*N28 -> 2.69864 | I28: =IF(J28=0, 0, 1.176) -> 1.176 | J28: =10.41*(1-(1-O28)*(1-P28)*(1-Q28)) -> 9.206604 | L28: 0.395 | M28: 0.56 | N28: 0.61 | O28: 0.66 | P28: 0 | Q28: 0.66
B29: API Server | C29: 1.2
C30: 1.2.1 | D30: Ensure that the --anonymous-auth argument is set to false | E30: 0 | F30: =IF(G30=0, "NONE", IF(G30<4, "LOW", IF(G30<7, "MEDIUM", IF(G30<9, "HIGH", "CRITICAL")))) -> MEDIUM | G30: =ROUND(((0.6*J30)+(0.4*H30)-1.5)*I30,1) -> 5 | H30: =20*L30*M30*N30 -> 9.9968 | I30: =IF(J30=0, 0, 1.176) -> 1.176 | J30: =10.41*(1-(1-O30)*(1-P30)*(1-Q30)) -> 2.86275 | L30: 1 | M30: 0.704 | N30: 0.71 | O30: 0.275 | P30: 0 | Q30: 0
C31: 1.2.2 | D31: Ensure that the --token-auth-file parameter is not set | E31: 1 | F31: =IF(G31=0, "NONE", IF(G31<4, "LOW", IF(G31<7, "MEDIUM", IF(G31<9, "HIGH", "CRITICAL")))) -> MEDIUM | G31: =ROUND(((0.6*J31)+(0.4*H31)-1.5)*I31,1) -> 6.5 | H31: =20*L31*M31*N31 -> 7.952 | I31: =IF(J31=0, 0, 1.176) -> 1.176 | J31: =10.41*(1-(1-O31)*(1-P31)*(1-Q31)) -> 6.4429767 | L31: 1 | M31: 0.56 | N31: 0.71 | O31: 0.275 | P31: 0.275 | Q31: 0.275
C32: 1.2.3 | D32: Ensure that the DenyServiceExternalIPs is set | E32: 0 | F32: =IF(G32=0, "NONE", IF(G32<4, "LOW", IF(G32<7, "MEDIUM", IF(G32<9, "HIGH", "CRITICAL")))) -> MEDIUM | G32: =ROUND(((0.6*J32)+(0.4*H32)-1.5)*I32,1) -> 4 | H32: =20*L32*M32*N32 -> 7.952 | I32: =IF(J32=0, 0, 1.176) -> 1.176 | J32: =10.41*(1-(1-O32)*(1-P32)*(1-Q32)) -> 2.86275 | L32: 1 | M32: 0.56 | N32: 0.71 | O32: 0 | P32: 0.275 | Q32: 0
C33: 1.2.4 | D33: Ensure that the --kubelet-client-certificate and --kubelet-client-key arguments are set as appropriate | E33: 1 | F33: =IF(G33=0, "NONE", IF(G33<4, "LOW", IF(G33<7, "MEDIUM", IF(G33<9, "HIGH", "CRITICAL")))) -> MEDIUM | G33: =ROUND(((0.6*J33)+(0.4*H33)-1.5)*I33,1) -> 4.9 | H33: =20*L33*M33*N33 -> 4.413472 | I33: =IF(J33=0, 0, 1.176) -> 1.176 | J33: =10.41*(1-(1-O33)*(1-P33)*(1-Q33)) -> 6.4429767 | L33: 0.646 | M33: 0.56 | N33: 0.61 | O33: 0.275 | P33: 0.275 | Q33: 0.275
C34: 1.2.5 | D34: Ensure that the --kubelet-certificate-authority argument is set as appropriate | E34: 1 | F34: =IF(G34=0, "NONE", IF(G34<4, "LOW", IF(G34<7, "MEDIUM", IF(G34<9, "HIGH", "CRITICAL")))) -> HIGH | G34: =ROUND(((0.6*J34)+(0.4*H34)-1.5)*I34,1) -> 7.9 | H34: =20*L34*M34*N34 -> 5.5483648 | I34: =IF(J34=0, 0, 1.176) -> 1.176 | J34: =10.41*(1-(1-O34)*(1-P34)*(1-Q34)) -> 10.000845 | L34: 0.646 | M34: 0.704 | N34: 0.61 | O34: 0.66 | P34: 0.66 | Q34: 0.66
C35: 1.2.6 | D35: Ensure that the --authorization-mode argument is not set to AlwaysAllow | E35: 1 | F35: =IF(G35=0, "NONE", IF(G35<4, "LOW", IF(G35<7, "MEDIUM", IF(G35<9, "HIGH", "CRITICAL")))) -> CRITICAL | G35: =ROUND(((0.6*J35)+(0.4*H35)-1.5)*I35,1) -> 10 | H35: =20*L35*M35*N35 -> 9.9968 | I35: =IF(J35=0, 0, 1.176) -> 1.176 | J35: =10.41*(1-(1-O35)*(1-P35)*(1-Q35)) -> 10.000845 | L35: 1 | M35: 0.704 | N35: 0.71 | O35: 0.66 | P35: 0.66 | Q35: 0.66
C36: 1.2.7 | D36: Ensure that the --authorization-mode argument includes Node | E36: 1 | F36: =IF(G36=0, "NONE", IF(G36<4, "LOW", IF(G36<7, "MEDIUM", IF(G36<9, "HIGH", "CRITICAL")))) -> LOW | G36: =ROUND(((0.6*J36)+(0.4*H36)-1.5)*I36,1) -> 2.7 | H36: =20*L36*M36*N36 -> 5.136992 | I36: =IF(J36=0, 0, 1.176) -> 1.176 | J36: =10.41*(1-(1-O36)*(1-P36)*(1-Q36)) -> 2.86275 | L36: 0.646 | M36: 0.56 | N36: 0.71 | O36: 0.275 | P36: 0 | Q36: 0
C37: 1.2.8 | D37: Ensure that the --authorization-mode argument includes RBAC | E37: 1 | F37: =IF(G37=0, "NONE", IF(G37<4, "LOW", IF(G37<7, "MEDIUM", IF(G37<9, "HIGH", "CRITICAL")))) -> MEDIUM | G37: =ROUND(((0.6*J37)+(0.4*H37)-1.5)*I37,1) -> 6.5 | H37: =20*L37*M37*N37 -> 7.952 | I37: =IF(J37=0, 0, 1.176) -> 1.176 | J37: =10.41*(1-(1-O37)*(1-P37)*(1-Q37)) -> 6.4429767 | L37: 1 | M37: 0.56 | N37: 0.71 | O37: 0.275 | P37: 0.275 | Q37: 0.275
C38: 1.2.9 | D38: Ensure that the admission control plugin EventRateLimit is set | E38: 0 | F38: =IF(G38=0, "NONE", IF(G38<4, "LOW", IF(G38<7, "MEDIUM", IF(G38<9, "HIGH", "CRITICAL")))) -> LOW | G38: =ROUND(((0.6*J38)+(0.4*H38)-1.5)*I38,1) -> 3.3 | H38: =20*L38*M38*N38 -> 6.4579328 | I38: =IF(J38=0, 0, 1.176) -> 1.176 | J38: =10.41*(1-(1-O38)*(1-P38)*(1-Q38)) -> 2.86275 | L38: 0.646 | M38: 0.704 | N38: 0.71 | O38: 0 | P38: 0.275 | Q38: 0
C39: 1.2.10 | D39: Ensure that the admission control plugin AlwaysAdmit is not set | E39: 1 | F39: =IF(G39=0, "NONE", IF(G39<4, "LOW", IF(G39<7, "MEDIUM", IF(G39<9, "HIGH", "CRITICAL")))) -> HIGH | G39: =ROUND(((0.6*J39)+(0.4*H39)-1.5)*I39,1) -> 7.7 | H39: =20*L39*M39*N39 -> 5.136992 | I39: =IF(J39=0, 0, 1.176) -> 1.176 | J39: =10.41*(1-(1-O39)*(1-P39)*(1-Q39)) -> 10.000845 | L39: 0.646 | M39: 0.56 | N39: 0.71 | O39: 0.66 | P39: 0.66 | Q39: 0.66
C40: 1.2.11 | D40: Ensure that the admission control plugin AlwaysPullImages is set | E40: 0 | F40: =IF(G40=0, "NONE", IF(G40<4, "LOW", IF(G40<7, "MEDIUM", IF(G40<9, "HIGH", "CRITICAL")))) -> LOW | G40: =ROUND(((0.6*J40)+(0.4*H40)-1.5)*I40,1) -> 2.3 | H40: =20*L40*M40*N40 -> 4.413472 | I40: =IF(J40=0, 0, 1.176) -> 1.176 | J40: =10.41*(1-(1-O40)*(1-P40)*(1-Q40)) -> 2.86275 | L40: 0.646 | M40: 0.56 | N40: 0.61 | O40: 0.275 | P40: 0 | Q40: 0
C41: 1.2.12 | D41: Ensure that the admission control plugin ServiceAccount is set | E41: 1 | F41: =IF(G41=0, "NONE", IF(G41<4, "LOW", IF(G41<7, "MEDIUM", IF(G41<9, "HIGH", "CRITICAL")))) -> MEDIUM | G41: =ROUND(((0.6*J41)+(0.4*H41)-1.5)*I41,1) -> 5.2 | H41: =20*L41*M41*N41 -> 5.136992 | I41: =IF(J41=0, 0, 1.176) -> 1.176 | J41: =10.41*(1-(1-O41)*(1-P41)*(1-Q41)) -> 6.4429767 | L41: 0.646 | M41: 0.56 | N41: 0.71 | O41: 0.275 | P41: 0.275 | Q41: 0.275
... C59: 1.2.30 | D59: Ensure that the --service-account-extend-token-expiration parameter is set to false | E59: 1 | F59: =IF(G59=0, "NONE", IF(G59<4, "LOW", IF(G59<7, "MEDIUM", IF(G59<9, "HIGH", "CRITICAL")))) -> LOW | G59: =ROUND(((0.6*J59)+(0.4*H59)-1.5)*I59,1) -> 2.7 | H59: =20*L59*M59*N59 -> 5.136992 | I59: =IF(J59=0, 0, 1.176) -> 1.176 | J59: =10.41*(1-(1-O59)*(1-P59)*(1-Q59)) -> 2.86275 | L59: 0.646 | M59: 0.56 | N59: 0.71 | O59: 0.275 | P59: 0 | Q59: 0
B60: Controller Manager | C60: 1.3
C61: 1.3.1 | D61: Ensure that the --terminated-pod-gc-threshold argument is set as appropriate | E61: 0 | F61: =IF(G61=0, "NONE", IF(G61<4, "LOW", IF(G61<7, "MEDIUM", IF(G61<9, "HIGH", "CRITICAL")))) -> LOW | G61: =ROUND(((0.6*J61)+(0.4*H61)-1.5)*I61,1) -> 2.7 | H61: =20*L61*M61*N61 -> 5.136992 | I61: =IF(J61=0, 0, 1.176) -> 1.176 | J61: =10.41*(1-(1-O61)*(1-P61)*(1-Q61)) -> 2.86275 | L61: 0.646 | M61: 0.56 | N61: 0.71 | O61: 0 | P61: 0.275 | Q61: 0
C62: 1.3.2 | D62: Ensure that the --profiling argument is set to false | E62: 1 | F62: =IF(G62=0, "NONE", IF(G62<4, "LOW", IF(G62<7, "MEDIUM", IF(G62<9, "HIGH", "CRITICAL")))) -> MEDIUM | G62: =ROUND(((0.6*J62)+(0.4*H62)-1.5)*I62,1) -> 4.1 | H62: =20*L62*M62*N62 -> 5.136992 | I62: =IF(J62=0, 0, 1.176) -> 1.176 | J62: =10.41*(1-(1-O62)*(1-P62)*(1-Q62)) -> 4.9382437 | L62: 0.646 | M62: 0.56 | N62: 0.71 | O62: 0.275 | P62: 0.275 | Q62: 0
C63: 1.3.3 | D63: Ensure that the --use-service-account-credentials argument is set to true | E63: 1 | F63: =IF(G63=0, "NONE", IF(G63<4, "LOW", IF(G63<7, "MEDIUM", IF(G63<9, "HIGH", "CRITICAL")))) -> HIGH | G63: =ROUND(((0.6*J63)+(0.4*H63)-1.5)*I63,1) -> 7.4 | H63: =20*L63*M63*N63 -> 4.413472 | I63: =IF(J63=0, 0, 1.176) -> 1.176 | J63: =10.41*(1-(1-O63)*(1-P63)*(1-Q63)) -> 10.000845 | L63: 0.646 | M63: 0.56 | N63: 0.61 | O63: 0.66 | P63: 0.66 | Q63: 0.66
C64: 1.3.4 | D64: Ensure that the --service-account-private-key-file argument is set as appropriate | E64: 1 | F64: =IF(G64=0, "NONE", IF(G64<4, "LOW", IF(G64<7, "MEDIUM", IF(G64<9, "HIGH", "CRITICAL")))) -> MEDIUM | G64: =ROUND(((0.6*J64)+(0.4*H64)-1.5)*I64,1) -> 4 | H64: =20*L64*M64*N64 -> 2.53232 | I64: =IF(J64=0, 0, 1.176) -> 1.176 | J64: =10.41*(1-(1-O64)*(1-P64)*(1-Q64)) -> 6.4429767 | L64: 0.646 | M64: 0.56 | N64: 0.35 | O64: 0.275 | P64: 0.275 | Q64: 0.275
C65: 1.3.5 | D65: Ensure that the --root-ca-file argument is set as appropriate | E65: 1 | F65: =IF(G65=0, "NONE", IF(G65<4, "LOW", IF(G65<7, "MEDIUM", IF(G65<9, "HIGH", "CRITICAL")))) -> HIGH | G65: =ROUND(((0.6*J65)+(0.4*H65)-1.5)*I65,1) -> 7.3 | H65: =20*L65*M65*N65 -> 5.5483648 | I65: =IF(J65=0, 0, 1.176) -> 1.176 | J65: =10.41*(1-(1-O65)*(1-P65)*(1-Q65)) -> 9.206604 | L65: 0.646 | M65: 0.704 | N65: 0.61 | O65: 0.66 | P65: 0 | Q65: 0.66
C66: 1.3.6 | D66: Ensure that the RotateKubeletServerCertificate argument is set to true | E66: 1 | F66: =IF(G66=0, "NONE", IF(G66<4, "LOW", IF(G66<7, "MEDIUM", IF(G66<9, "HIGH", "CRITICAL")))) -> LOW | G66: =ROUND(((0.6*J66)+(0.4*H66)-1.5)*I66,1) -> 3.3 | H66: =20*L66*M66*N66 -> 6.4579328 | I66: =IF(J66=0, 0, 1.176) -> 1.176 | J66: =10.41*(1-(1-O66)*(1-P66)*(1-Q66)) -> 2.86275 | L66: 0.646 | M66: 0.704 | N66: 0.71 | O66: 0 | P66: 0.275 | Q66: 0
...

Sheet NSA-CISA k8s hardening
A1: Title | B1: NSA-CISA Kubernetes Hardening Guide
A2: Version | B2: 1.2
A4: Section | B4: Title | C4: Subtitle
A5: Kubernetes Pod Security
B6: "Non-root" containers and "rootless" container engines
B7: Immutable container file systems
B8: Building secure container images
B9: Pod security enforcement
B10: Protecting Pod service account tokens
B11: Hardening container environments
A12: Network separation and hardening
B13: Namespaces
B14: Network policies
B15: Resource policies
B16: Control plane hardening
C17: Etcd
C18: Kubeconfig Files
B19: Worker node segmentation
B20: Encryption
B21: Secrets
B22: Protecting sensitive cloud infrastructure
A23: Authentication and authorization
B24: Authentication
B25: Role-based access control
A26: Audit Logging and Threat Detection
B27: Logging
C28: Kubernetes native audit logging configuration
C29: Worker node and container logging
C30: Seccomp: audit mode
C31: Syslog
C32: SIEM platforms
C33: Service meshes
C34: Fault tolerance
B35: Threat Detection
C36: Alerting
B37: Tools
A38: Upgrading and application security practices

Sheet K8S STIG
A1: Title | B1: Kubernetes Secure Technical Implementation Guide (STIG)
A2: Version | B2: Ver 2, Rel 3
A5: Title | B5: Group ID | C5: Rule ID | D5: Description | E5: Automated
A6: CNTR-K8-000150 | B6: V-242376 | C6: SV-242376r960759 | D6: The Kubernetes Controller Manager must use TLS 1.2, at a minimum | E6: 0
A7: CNTR-K8-000160 | B7: V-242377 | C7: SV-242377r960759 | D7: The Kubernetes Scheduler must use TLS 1.2, at a minimum | E7: 0
A8: CNTR-K8-000170 | B8: V-242378 | C8: SV-242378r960759 | D8: The Kubernetes API Server must use TLS 1.2, at a minimum | E8: 0
A9: CNTR-K8-000180 | B9: V-242379 | C9: SV-242379r960759 | D9: The Kubernetes etcd must use TLS (--auto-tls) | E9: 0
A10: CNTR-K8-000190 | B10: V-242380 | C10: SV-242380r960759 | D10: The Kubernetes etcd must use TLS (--peer-auto-tls) | E10: 0
A11: CNTR-K8-000220 | B11: V-242381 | C11: SV-242381r1043176 | D11: The Kubernetes Controller Manager must create unique service accounts for each work payload. | E11: 0
A12: CNTR-K8-000270 | B12: V-242382 | C12: SV-242382r960792 | D12: The Kubernetes API Server must enable Node,RBAC as the authorization mode. | E12: 0
A13: CNTR-K8-000290 | B13: V-242383 | C13: SV-242383r960801 | D13: User-managed resources must be created in dedicated namespaces. | E13: 0
A14: CNTR-K8-000300 | B14: V-242384 | C14: SV-242384r960792 | D14: The Kubernetes Scheduler must have secure binding. | E14: 0
A15: CNTR-K8-000310 | B15: V-242385 | C15: SV-242385r960792 | D15: The Kubernetes Controller Manager must have secure binding. | E15: 0
A16: CNTR-K8-000320 | B16: V-242386 | C16: SV-242386r960792 | D16: The Kubernetes API server must have the insecure port flag disabled. | E16: 0
A17: CNTR-K8-000330 | B17: V-242387 | C17: SV-242387r960792 | D17: The Kubernetes Kubelet must have the "readOnlyPort" flag disabled. | E17: 0
... A33: CNTR-K8-000850 | B33: V-242404 | C33: SV-242404r960960 | D33: Kubernetes Kubelet must deny hostname override. | E33: 0
A34: CNTR-K8-000860 | B34: V-242405 | C34: SV-242405r960960 | D34: The Kubernetes manifests must be owned by root. | E34: 0 | F34: V-242444
A35: CNTR-K8-000880 | B35: V-242406 | C35: SV-242406r960960 | D35: The Kubernetes KubeletConfiguration file must be owned by root. | E35: 0 | F35: V-242457
A36: CNTR-K8-000890 | B36: V-242407 | C36: SV-242407r960960 | D36: The Kubernetes KubeletConfiguration files must have file permissions set to 644 or more restrictive. | E36: 0 | F36: V-242456
A37: CNTR-K8-000900 | B37: V-242408 | C37: SV-242408r960960 | D37: The Kubernetes manifest files must have least privileges. | E37: 0
A38: CNTR-K8-000910 | B38: V-242409 | C38: SV-242409r960963 | D38: Kubernetes Controller Manager must disable profiling. | E38: 0
A39: CNTR-K8-000920 | B39: V-242410 | C39: SV-242410r1043177 | D39: The Kubernetes API Server must enforce ports, protocols, and services | E39: 0
A40: CNTR-K8-000930 | B40: V-242411 | C40: SV-242411r1043177 | D40: The Kubernetes Scheduler must enforce ports, protocols, and services | E40: 0
A41: CNTR-K8-000940 | B41: V-242412 | C41: SV-242412r1043177 | D41: The Kubernetes Controllers must enforce ports, protocols, and services | E41: 0
A42: CNTR-K8-000950 | B42: V-242413 | C42: SV-242413r1043177 | D42: The Kubernetes etcd must enforce ports, protocols, and services | E42: 0
A43: CNTR-K8-000960 | B43: V-242414 | C43: SV-242414r1043177 | D43: The Kubernetes cluster must use non-privileged host ports for user pods. | E43: 0
A44: CNTR-K8-001160 | B44: V-242415 | C44: SV-242415r1069466 | D44: Secrets in Kubernetes must not be stored as environment variables. | E44: 0
A45: CNTR-K8-001300 | B45: V-245541 | C45: SV-245541r1069469 | D45: Kubernetes Kubelet must not disable timeouts. | E45: 0
A46: CNTR-K8-001360 | B46: V-242417 | C46: SV-242417r961095 | D46: Kubernetes must separate user functionality. | E46: 0
A47: CNTR-K8-001400 | B47: V-242418 | C47: SV-242418r1043178 | D47: The Kubernetes API server must use approved cipher suites. | E47: 0
A48: CNTR-K8-001420 | B48: V-242420 | C48: SV-242420r1043178 | D48: Kubernetes Kubelet must have the SSL Certificate Authority set. | E48: 0
... A73: CNTR-K8-002720 | B73: V-242443 | C73: SV-242443r961683 | D73: Kubernetes must contain the latest updates as authorized by IAVMs, CTOs, DTMs, and STIGs. | E73: 0
A74: CNTR-K8-003110 | B74: V-242444 | C74: SV-242444r961863 | D74: The Kubernetes component manifests must be owned by root. | E74: 0 | F74: V-242405
A75: CNTR-K8-003120 | B75: V-242445 | C75: SV-242445r961863 | D75: The Kubernetes component etcd must be owned by etcd. | E75: 0
A76: CNTR-K8-003130 | B76: V-242446 | C76: SV-242446r961863 | D76: The Kubernetes conf files must be owned by root. | E76: 0
A77: CNTR-K8-003140 | B77: V-242447 | C77: SV-242447r961863 | D77: The Kubernetes Kube Proxy kubeconfig must have file permissions set to 644 or more restrictive. | E77: 0
A78: CNTR-K8-003150 | B78: V-242448 | C78: SV-242448r961863 | D78: The Kubernetes Kube Proxy kubeconfig must be owned by root. | E78: 0
A79: CNTR-K8-003160 | B79: V-242449 | C79: SV-242449r961863 | D79: The Kubernetes Kubelet certificate authority file must have file permissions set to 644 or more restrictive. | E79: 0
A80: CNTR-K8-003170 | B80: V-242450 | C80: SV-242450r961863 | D80: The Kubernetes Kubelet certificate authority must be owned by root. | E80: 0
A81: CNTR-K8-003180 | B81: V-242451 | C81: SV-242451r961863 | D81: The Kubernetes component PKI must be owned by root. | E81: 0
...

Sheet BSI
A1: Title | B1: BSI - APP.4.4 Kubernetes
A2: Version | B2: Ver 2, Rel 3
A4: Numbering | B4: Title
A5: 3.1 | B5: Basis-Anforderungen
A6: APP.4.4.A1 | B6: Planung der Separierung der Anwendungen
A7: APP.4.4.A2 | B7: Planung der Automatisierung mit CI/CD
A8: APP.4.4.A3 | B8: Identitäts- und Berechtigungsmanagement bei Kubernetes
A9: APP.4.4.A4 | B9: Separierung von Pods
A10: APP.4.4.A5 | B10: Datensicherung im Cluster
A11: 3.2 | B11: Standard-Anforderungen
A12: APP.4.4.A6 | B12: Initialisierung von Pods
A13: APP.4.4.A7 | B13: Separierung der Netze bei Kubernetes
A14: APP.4.4.A8 | B14: Absicherung von Konfigurationsdateien bei Kubernetes
A15: APP.4.4.A9 | B15: Nutzung von Kubernetes Service-Accounts
A16: APP.4.4.A10 | B16: Absicherung von Prozessen der Automatisierung
A17: APP.4.4.A11 | B17: Überwachung der Container
A18: APP.4.4.A12 | B18: Absicherung der Infrastruktur-Anwendungen
A19: 3.3 | B19: Anforderungen bei erhöhtem Schutzbedarf
A20: APP.4.4.A13 | B20: Automatisierte Auditierung der Konfiguration
A21: APP.4.4.A14 | B21: Verwendung dedizierter Nodes
A22: APP.4.4.A15 | B22: Trennung von Anwendungen auf Node- und Cluster-Ebene
A23: APP.4.4.A16 | B23: Verwendung von Operatoren
A24: APP.4.4.A17 | B24: Attestierung von Nodes
A25: APP.4.4.A18 | B25: Verwendung von Mikro-Segmentierung
A26: APP.4.4.A19 | B26: Hochverfügbarkeit von Kubernetes
A27: APP.4.4.A20 | B27: Verschlüsselte Datenhaltung bei Pods
A28: APP.4.4.A21 | B28: Regelmäßiger Restart von Pods

Sheet PCI Container Guidance
A1: Title | B1: Guidance for Containers and Container Orchestration Tools
A2: Version | B2: 1
A4: Numbering | B4: Title
A5: 1 | B5: Authentication mechanisms should store credentials in a properly secured datastore
A6: 1.1.a | B6: All access requires authentication and individual accountability
A7: 1.2.a | B7: All user credentials should be tied to specific individuals
A8: 1.3.a | B8: All credentials used by the orchestration system should be revokable
A9: 1.4.a | B9: Authentication mechanisms should store credentials in a properly secured datastore
A10: 1.5.a | B10: Credentials should only be provided to running services where explicitly required
A11: 1.5.b | B11: Service accounts should be configured for least privilege
A12: 1.6.a | B12: Interactive users should use multi-factor authentication
A13: 2 | B13: Authorization
A14: 2.1.a | B14: Access granted for users or services should be on a least privilege basis
A15: 2.2.a | B15: All access granted to the orchestration tool should be capable of modification
A16: 2.2.b | B16: Access groups should not be hard-coded
A17: 2.3.a | B17: Use manual and automated means to regularly audit implemented permissions
A18: 3 | B18: Workload Security
A19: 3.1.a | B19: Workloads running in the orchestration system should be configured to prevent access to the underlying cluster nodes by default.
A20: 3.2.a | B20: Workload definitions/manifests should target specific known versions of any container images
A21: 3.3.a | B21: All container images running in the cluster should come from trusted sources.
A22: 4 | B22: Network Security
A23: 4.1.a | B23: Container orchestration tool networks should be configured on a default deny basis, with access explicitly required only for the operation of the applications being allowed.
A24: 4.2.a | B24: Access to orchestration system components and other administrative APIs should be restricted using an explicit allow-list of IP addresses.
A25: 4.3.a | B25: All traffic with orchestration system components APIs should be over encrypted connections, ensuring encryption key rotation meets PCI key and secret requirements.
A26: 5 | B26: PKI
A27: 5.1.a | B27: Where revocation of certificates is not supported, certificate-based authentication should not be used.
A28: 5.1.b | B28: Rotate certificates as required by PCI or customer policies or if any containers are compromised.
A29: 5.2.a | B29: The certificates issued by orchestration tools should not be trusted outside of the container orchestrator environment, as the container orchestrator’s Certificate Authority private key can have weaker protection than other enterprise PKI trust chains.
A30: 6 | B30: Secrets Management
A31: 6.1.a | B31: All secrets needed for the operation of applications hosted on the orchestration platform should be held in encrypted dedicated secrets management systems.
A32: 6.2.a | B32: Apply version control for secrets, so it is easy to refresh or revoke it in case of a compromise.
A33: 7 | B33: Container Orchestration Tool Auditing
A34: 7.1.a | B34: Access to the orchestration system API(s) should be audited and monitored for indications of unauthorized access. Audit logs should be securely stored on a centralized system.
A35: 8 | B35: Container Monitoring
A36: 8.1.a | B36: Centralized logging of container activity should be implemented and allow for correlation of events across instances of the same container.
A37: 8.2.a | B37: Controls should be implemented to detect the adding and execution of new binaries and unauthorized modification of container files to running containers.
A38: 9 | B38: Container Runtime Security
A39: 9.1.a | B39: Where high-risk workloads are identified, consideration should be given to using either container runtimes that provide hypervisorlevel isolation for the workload or dedicated security sandboxes.
A40: 9.2.a | B40: Where Windows containers are used to run application containers, Hyper-V isolation should be deployed in-line with Microsoft’s security guidance.
A41: 10 | B41: Patching
...

Sheet MS TM for K8S
A1: Title | B1: Microsoft Threat Matrix for Kubernetes
A2: Version | B2: 45944
A4: Numbering | B4: Title
A5: MS-M9001 | B5: Multi-factor authentication
A6: MS-M9002 | B6: Restrict access to the API server using IP firewall
A7: MS-M9003 | B7: Adhere to least-privilege principle
A8: MS-M9004 | B8: Secure CI/CD environment
A9: MS-M9005 | B9: Image assurance policy
A10: MS-M9005.001 | B10: Gate generated images in CI/CD pipeline
A11: MS-M9005.002 | B11: Gate images pushed to registries
A12: MS-M9005.003 | B12: Gate images deployed to Kubernetes cluster
A13: MS-M9006 | B13: Enable Just In Time access to API server
A14: MS-M9007 | B14: Network intrusion prevention
A15: MS-M9008 | B15: Limit access to services over network
... A39: MS-M9032 | B39: Avoid using web-hosted manifest for Kubelet

Sheet Kubernetes security checklists
A1: Title | B1: Security Checklist & Application Security Checklist | C1: Origins | D1: https://kubernetes.io/docs/concepts/security/security-checklist/
A2: Version | B2: 45944 | D2: https://kubernetes.io/docs/concepts/security/application-security-checklist/
A4: Origin | B4: Category | C4: Item
A5: Security Checklist | B5: Authentication & Authorization | C5: system:masters group is not used for user or component authentication after bootstrapping
A6: Security Checklist | B6: Authentication & Authorization | C6: The kube-controller-manager is running with --use-service-account-credentials enabled.
A7: Security Checklist | B7: Authentication & Authorization | C7: The root certificate is protected (either an offline CA, or a managed online CA with effective access controls).
A8: Security Checklist | B8: Authentication & Authorization | C8: Intermediate and leaf certificates have an expiry date no more than 3 years in the future.
A9: Security Checklist | B9: Authentication & Authorization | C9: A process exists for periodic access review, and reviews occur no more than 24 months apart.
A10: Security Checklist | B10: Authentication & Authorization | C10: The Role Based Access Control Good Practices are followed for guidance related to authentication and authorization.
A11: Security Checklist | B11: Network security | C11: CNI plugins in use support network policies.
A12: Security Checklist | B12: Network security | C12: Ingress and egress network policies are applied to all workloads in the cluster.
A13: Security Checklist | B13: Network security | C13: Default network policies within each namespace, selecting all pods, denying everything, are in place.
A14: Security Checklist | B14: Network security | C14: If appropriate, a service mesh is used to encrypt all communications inside of the cluster.
A15: Security Checklist | B15: Network security | C15: Access from the workloads to the cloud metadata API is filtered.
... A59: Application Security Checklist | B59: Application design | C59: Follow the right security principles when designing applications.
A60: Application Security Checklist | B60: Application design | C60: Memory limit is set for the workloads with a limit equal to or greater than the request. | D60: see C26
A61: Application Security Checklist | B61: Application design | C61: CPU limit might be set on sensitive workloads.
A62: Application Security Checklist | B62: Service account | C62: Avoid using the default ServiceAccount. Instead, create ServiceAccounts for each workload or microservice.
A63: Application Security Checklist | B63: Service account | C63: automountServiceAccountToken should be set to false unless the pod specifically requires access to the Kubernetes API to operate.
A64: Application Security Checklist | B64: Pod-level securityContext recommendations | C64: Set runAsNonRoot: true.
A65: Application Security Checklist | B65: Pod-level securityContext recommendations | C65: Configure the container to execute as a less privileged user (for example, using runAsUser and runAsGroup), and configure appropriate permissions on files or directories inside the container image.
A66: Application Security Checklist | B66: Pod-level securityContext recommendations | C66: Optionally add a supplementary group with fsGroup to access persistent volumes.
A67: Application Security Checklist | B67: Pod-level securityContext recommendations | C67: The application deploys into a namespace that enforces an appropriate Pod security standard.
A68: Application Security Checklist | B68: Container-level securityContext recommendations | C68: Disable privilege escalations using allowPrivilegeEscalation: false.
A69: Application Security Checklist | B69: Container-level securityContext recommendations | C69: Configure the root filesystem to be read-only with readOnlyRootFilesystem: true.
A70: Application Security Checklist | B70: Container-level securityContext recommendations | C70: Avoid running privileged containers (set privileged: false).
A71: Application Security Checklist | B71: Container-level securityContext recommendations | C71: Drop all capabilities from the containers and add back only specific ones that are needed for operation of the container.
A72: Application Security Checklist | B72: Role Based Access Control | C72: Permissions such as create, patch, update and delete should be only granted if necessary.
... A81: Application Security Checklist | B81: Runtime classes | C81: Configure appropriate runtime classes for containers

Sheet OWASP
A1: Title: | B1: OWASP Kubernetes Security Cheat Sheet
A2: Version: | B2: 45947
A3: Origin: | B3: https://cheatsheetseries.owasp.org/cheatsheets/Kubernetes_Security_Cheat_Sheet.html
A5: Section | B5: Subsection
A6: S1 - Securing Kubernetes Hosts
B7: Updating Kubernetes | D7: 1
A8: S2 - Securing Kubernetes Components
